Workbook

Sheet Occupancy
B1: Year | M1: 2024 | N1: 2024 | P1: 2024 | Q1: 2024 | R1: 2024 | S1: 2024 | U1: 2024 | V1: 2024 | W1: 2024 | X1: 2024 | Z1: 2024 | AA1: 2024 | AB1: 2024 | AC1: 2024 | AD1: 2024 | AE1: 2024 | AF1: 2024 | AG1: 2024 | AH1: 2024 | AI1: 2024 | AJ1: 2024 | AK1: 2024 | AM1: 2024 | AN1: 2024
B2: Year-Quarter | M2: 2024-Q2 | N2: 2024-Q2 | P2: 2024-Q2 | Q2: 2024-Q2 | R2: 2024-Q2 | S2: 2024-Q2 | U2: 2024-Q2 | V2: 2024-Q2 | W2: 2024-Q2 | X2: 2024-Q2 | Z2: 2024-Q2 | AA2: 2024-Q2 | AB2: 2024-Q1 | AC2: 2024-Q1 | AD2: 2024-Q1 | AE2: 2024-Q1 | AF2: 2024-Q1 | AG2: 2024-Q1 | AH2: 2024-Q1 | AI2: 2024-Q1 | AJ2: 2024-Q1 | AK2: 2024-Q1 | AM2: 2024-Q1 | AN2: 2024-Q1
B3: Month | C3: August | D3: Jun | F3: Jun | G3: Jun | H3: July | I3: Jun | K3: Jun | L3: Jun | M3: Jun | N3: Jun | P3: Jun | Q3: Jun | R3: May | S3: May | U3: May | V3: May | W3: Apr | X3: Apr | Z3: Apr | AA3: Apr | AB3: Mar | AC3: Mar | AD3: Mar | AE3: Mar | AF3: Feb | AG3: Feb | AH3: Feb | AI3: Feb | AJ3: Jan | AK3: Jan | AM3: Jan | AN3: Jan | AO3: 2024 YTD | AP3: Jan | AQ3: Jan | AR3: Jan
A4: CampusName | B4: LevelOfCare | C4: Resident Days | D4: In Service Days | E4: 31 | F4: Occupancy % | G4: Budget Occupancy % | H4: Resident Days | I4: In Service Days | J4: 31 | K4: Occupancy % | L4: Budget Occupancy % | M4: Resident Days | N4: In Service Days | O4: 30 | P4: Occupancy % | Q4: Budget Occupancy % | R4: Resident Days | S4: In Service Days | T4: 31 | U4: Occupancy % | V4: Budget Occupancy % | W4: Resident Days | X4: In Service Days | Y4: 30 | Z4: Occupancy % | AA4: Budget Occupancy % | AB4: Resident Days | AC4: In Service Days | AD4: Occupancy % | AE4: Budget Occupancy % | AF4: Resident Days | AG4: In Service Days | AH4: Occupancy % | AI4: Budget Occupancy % | AJ4: Resident Days | AK4: In Service Days | AL4: 31 | AM4: Occupancy % | AN4: Budget Occupancy % | AO4: Resident Days | AP4: In Service Days | AQ4: Occupancy % | AR4: Budget Occupancy %
A5: Totals | C5: =C6+C10+C14+C21+C25+C29+C18+C19+C20 -> 86021 | D5: =D6+D10+D14+D21+D25+D29+D18+D19+D20 -> 96937 | E5: =D5/$E$4 -> 3127 | F5: =C5/D5 -> 0.88739078 | G5: 0.90231458 | H5: =H6+H10+H14+H21+H25+H29+H18+H19+H20 -> 85978 | I5: =I6+I10+I14+I21+I25+I29+I18+I19+I20 -> 96937 | J5: =I5/$J$4 -> 3127 | K5: =H5/I5 -> 0.88694719 | L5: 0.90231458 | M5: =M6+M10+M14+M21+M25+M29+M18+M19+M20 -> 83034 | N5: =N6+N10+N14+N21+N25+N29+N18+N19+N20 -> 93810 | O5: =N5/$O$4 -> 3127 | P5: =M5/N5 -> 0.88512952 | Q5: 0.90231458 | R5: =R6+R10+R14+R21+R25+R29+R18+R19+R20 -> 85734 | S5: =S6+S10+S14+S21+S25+S29+S18+S19+S20 -> 96937 | T5: =S5/$T$4 -> 3127 | U5: =R5/S5 -> 0.88443009 | V5: 0.90167519 | W5: =W6+W10+W14+W21+W25+W29+W18+W19+W20 -> 83664 | X5: =X6+X10+X14+X21+X25+X29+X18+X19+X20 -> 93844 | Y5: =X5/$Y$4 -> 3128.1333 | Z5: =W5/X5 -> 0.8915221 | AA5: 0.9013555 | AB5: =AB6+AB10+AB14+AB21+AB25+AB29+AB18+AB19+AB20 -> 86615 | AC5: =AC6+AC10+AC14+AC21+AC25+AC29+AC18+AC19+AC20 -> 96999 | AD5: =AB5/AC5 -> 0.89294735 | AE5: 0.90103581 | AF5: =AF6+AF10+AF14+AF21+AF25+AF29+AF18+AF19+AF20 -> 81450 | AG5: =AG6+AG10+AG14+AG21+AG25+AG29+AG18+AG19+AG20 -> 90773 | AH5: =AF5/AG5 -> 0.89729325 | AI5: 0.90023657 | AJ5: 86416 | AK5: 97092 | AL5: =AK5/$AL$4 -> 3132 | AM5: 0.89004243 | AN5: 0.89943734 | AO5: =M5+R5+W5+AB5+AF5+AJ5+H5+C5 -> 678912 | AP5: =N5+S5+X5+AC5+AG5+AK5+I5+D5 -> 763329 | AQ5: =AO5/AP5 -> 0.88940942 | AR5: 0.901
A6: Asbury Methodist Village | B6: Totals | C6: =SUM(C7:C9) -> 29048 | D6: =SUM(D7:D9) -> 35433 | E6: =D6/$E$4 -> 1143 | F6: =C6/D6 -> 0.81980075 | G6: 0.85504812 | H6: =SUM(H7:H9) -> 29073 | I6: =SUM(I7:I9) -> 35433 | J6: =I6/$J$4 -> 1143 | K6: 0.82496355 | L6: 0.85504812 | M6: =SUM(M7:M9) -> 28280 | N6: 34290 | O6: =N6/$O$4 -> 1143 | P6: 0.82496355 | Q6: 0.85504812 | R6: 28953 | S6: 35433 | T6: =S6/$T$4 -> 1143 | U6: 0.81711963 | V6: 0.85417323 | W6: 28609 | X6: 34290 | Y6: =X6/$Y$4 -> 1143 | Z6: 0.83432488 | AA6: 0.85329834 | AB6: 29529 | AC6: 35433 | AD6: 0.83337567 | AE6: 0.85242345 | AF6: 27748 | AG6: 33147 | AH6: 0.8371195 | AI6: 0.85023622 | AJ6: 29512 | AK6: 35433 | AL6: =AK6/$AL$4 -> 1143 | AM6: 0.83289589 | AN6: 0.84892388 | AO6: =M6+R6+W6+AB6+AF6+AJ6+H6+C6 -> 230752 | AP6: =N6+S6+X6+AC6+AG6+AK6+I6+D6 -> 278892 | AQ6: =AO6/AP6 -> 0.82738838 | AR6: 0.852
A7: Asbury Methodist Village | B7: AL | C7: =4276-463 -> 3813 | D7: 4123 | E7: =D7/$E$4 -> 133 | F7: =C7/D7 -> 0.92481203 | G7: 0.90977444 | H7: 3781 | I7: 4123 | J7: =I7/$J$4 -> 133 | K7: =H7/I7 -> 0.91705069 | L7: 0.90977444 | M7: 3594 | N7: 3990 | O7: =N7/$O$4 -> 133 | P7: 0.90050125 | Q7: 0.90977444 | R7: 3587 | S7: 4123 | T7: =S7/$T$4 -> 133 | U7: 0.86999757 | V7: 0.90977444 | W7: 3563 | X7: 3990 | Y7: =X7/$Y$4 -> 133 | Z7: 0.89298246 | AA7: 0.90977444 | AB7: 3610 | AC7: 4123 | AD7: 0.87557604 | AE7: 0.90977444 | AF7: 3414 | AG7: 3857 | AH7: 0.88514389 | AI7: 0.90977444 | AJ7: 3660 | AK7: 4123 | AL7: =AK7/$AL$4 -> 133 | AM7: 0.88770313 | AN7: 0.90977444 | AO7: =M7+R7+W7+AB7+AF7+AJ7+H7+C7 -> 29022 | AP7: =N7+S7+X7+AC7+AG7+AK7+I7+D7 -> 32452 | AQ7: =AO7/AP7 -> 0.89430544 | AR7: 0.91
A8: Asbury Methodist Village | B8: IL | C8: =25853-6207 -> 19646 | D8: 25575 | E8: =D8/$E$4 -> 825 | F8: =C8/D8 -> 0.76817204 | G8: 0.8230303 | H8: 19729 | I8: 25575 | J8: =I8/$J$4 -> 825 | K8: =H8/I8 -> 0.7714174 | L8: 0.8230303 | M8: 19282 | N8: 24750 | O8: =N8/$O$4 -> 825 | P8: 0.77907071 | Q8: 0.8230303 | R8: 20048 | S8: 25575 | T8: =S8/$T$4 -> 825 | U8: 0.78389052 | V8: 0.82181818 | W8: 19485 | X8: 24750 | Y8: =X8/$Y$4 -> 825 | Z8: 0.78727273 | AA8: 0.82060606 | AB8: 20249 | AC8: 25575 | AD8: 0.79174976 | AE8: 0.81939394 | AF8: 19046 | AG8: 23925 | AH8: 0.79607106 | AI8: 0.81636364 | AJ8: 20467 | AK8: 25575 | AL8: =AK8/$AL$4 -> 825 | AM8: 0.8002737 | AN8: 0.81454545 | AO8: =M8+R8+W8+AB8+AF8+AJ8+H8+C8 -> 157952 | AP8: =N8+S8+X8+AC8+AG8+AK8+I8+D8 -> 201300 | AQ8: =AO8/AP8 -> 0.78465971 | AR8: 0.819
A9: Asbury Methodist Village | B9: SNF | C9: 5589 | D9: 5735 | E9: =D9/$E$4 -> 185 | F9: =C9/D9 -> 0.97454228 | G9: 0.95848649 | H9: 5563 | I9: 5735 | J9: =I9/$J$4 -> 185 | K9: =H9/I9 -> 0.97000872 | L9: 0.95848649 | M9: 5404 | N9: 5550 | O9: =N9/$O$4 -> 185 | P9: 0.97531532 | Q9: 0.95848649 | R9: 5318 | S9: 5735 | T9: =S9/$T$4 -> 185 | U9: 0.92728858 | V9: 0.95848649 | W9: 5561 | X9: 5550 | Y9: =X9/$Y$4 -> 185 | Z9: 1.001982 | AA9: 0.95848649 | AB9: 5670 | AC9: 5735 | AD9: 0.98866609 | AE9: 0.95848649 | AF9: 5288 | AG9: 5365 | AH9: 0.98564772 | AI9: 0.95848649 | AJ9: 5385 | AK9: 5735 | AL9: =AK9/$AL$4 -> 185 | AM9: 0.93897123 | AN9: 0.95848649 | AO9: =M9+R9+W9+AB9+AF9+AJ9+H9+C9 -> 43778 | AP9: =N9+S9+X9+AC9+AG9+AK9+I9+D9 -> 45140 | AQ9: =AO9/AP9 -> 0.9698272 | AR9: 0.958
A10: Asbury Solomons | B10: Totals | C10: =C11+C12+C13 -> 10968 | D10: =D11+D12+D13 -> 11532 | E10: =D10/$E$4 -> 372 | F10: =C10/D10 -> 0.95109261 | G10: 0.93069892 | H10: =H11+H12+H13 -> 10839 | I10: =I11+I12+I13 -> 11532 | J10: =I10/$J$4 -> 372 | K10: =H10/I10 -> 0.93990635 | L10: 0.93069892 | M10: =M11+M12+M13 -> 10255 | N10: =N11+N12+N13 -> 11160 | O10: =N10/$O$4 -> 372 | P10: =M10/N10 -> 0.91890681 | Q10: 0.93069892 | R10: =R11+R12+R13 -> 10576 | S10: =S11+S12+S13 -> 11532 | T10: =S10/$T$4 -> 372 | U10: =R10/S10 -> 0.91710024 | V10: 0.93069892 | W10: =W11+W12+W13 -> 10250 | X10: =X11+X12+X13 -> 11160 | Y10: =X10/$Y$4 -> 372 | Z10: =W10/X10 -> 0.91845878 | AA10: 0.93069892 | AB10: =AB11+AB12+AB13 -> 10466 | AC10: =AC11+AC12+AC13 -> 11532 | AD10: =AB10/AC10 -> 0.90756157 | AE10: 0.93069892 | AF10: =AF11+AF12+AF13 -> 9910 | AG10: =AG11+AG12+AG13 -> 10788 | AH10: =AF10/AG10 -> 0.91861327 | AI10: 0.93069892 | AJ10: 10720 | AK10: 11532 | AL10: =AK10/$AL$4 -> 372 | AM10: 0.92958724 | AN10: 0.93069892 | AO10: =M10+R10+W10+AB10+AF10+AJ10+H10+C10 -> 83984 | AP10: =N10+S10+X10+AC10+AG10+AK10+I10+D10 -> 90768 | AQ10: =AO10/AP10 -> 0.92526 | AR10: 0.931
A11: Asbury Solomons | B11: AL | C11: =806-62 -> 744 | D11: 744 | E11: =D11/$E$4 -> 24 | F11: =C11/D11 -> 1 | G11: 0.98 | H11: =806-62 -> 744 | I11: 744 | J11: =I11/$J$4 -> 24 | K11: =H11/I11 -> 1 | L11: 0.98 | M11: 710 | N11: 720 | O11: =N11/$O$4 -> 24 | P11: =M11/N11 -> 0.98611111 | Q11: 0.98 | R11: 722 | S11: 744 | T11: =S11/$T$4 -> 24 | U11: =R11/S11 -> 0.97043011 | V11: 0.98 | W11: 714 | X11: 720 | Y11: =X11/$Y$4 -> 24 | Z11: =W11/X11 -> 0.99166667 | AA11: 0.98 | AB11: 744 | AC11: 744 | AD11: =AB11/AC11 -> 1 | AE11: 0.98 | AF11: 691 | AG11: 696 | AH11: =AF11/AG11 -> 0.99281609 | AI11: 0.98 | AJ11: 729 | AK11: 744 | AL11: =AK11/$AL$4 -> 24 | AM11: 0.97983871 | AN11: 0.98 | AO11: =M11+R11+W11+AB11+AF11+AJ11+H11+C11 -> 5798 | AP11: =N11+S11+X11+AC11+AG11+AK11+I11+D11 -> 5856 | AQ11: =AO11/AP11 -> 0.99009563 | AR11: 0.98
A12: Asbury Solomons | B12: IL | C12: =12004-3027 -> 8977 | D12: 9300 | E12: =D12/$E$4 -> 300 | F12: =C12/D12 -> 0.96526882 | G12: 0.94233333 | H12: 9004 | I12: 9300 | J12: =I12/$J$4 -> 300 | K12: =H12/I12 -> 0.96817204 | L12: 0.94233333 | M12: 8507 | N12: 9000 | O12: =N12/$O$4 -> 300 | P12: =M12/N12 -> 0.94522222 | Q12: 0.94233333 | R12: 8850 | S12: 9300 | T12: =S12/$T$4 -> 300 | U12: =R12/S12 -> 0.9516129 | V12: 0.94233333 | W12: 8563 | X12: 9000 | Y12: =X12/$Y$4 -> 300 | Z12: =W12/X12 -> 0.95144444 | AA12: 0.94233333 | AB12: 8790 | AC12: 9300 | AD12: =AB12/AC12 -> 0.94516129 | AE12: 0.94233333 | AF12: 8218 | AG12: 8700 | AH12: =AF12/AG12 -> 0.9445977 | AI12: 0.94233333 | AJ12: 8932 | AK12: 9300 | AL12: =AK12/$AL$4 -> 300 | AM12: 0.96043011 | AN12: 0.94233333 | AO12: =M12+R12+W12+AB12+AF12+AJ12+H12+C12 -> 69841 | AP12: =N12+S12+X12+AC12+AG12+AK12+I12+D12 -> 73200 | AQ12: =AO12/AP12 -> 0.95411202 | AR12: 0.942
A13: Asbury Solomons | B13: SNF | C13: 1247 | D13: 1488 | E13: =D13/$E$4 -> 48 | F13: =C13/D13 -> 0.83803763 | G13: 0.83333333 | H13: 1091 | I13: 1488 | J13: =I13/$J$4 -> 48 | K13: =H13/I13 -> 0.73319892 | L13: 0.83333333 | M13: 1038 | N13: =48*30 -> 1440 | O13: =N13/$O$4 -> 48 | P13: =M13/N13 -> 0.72083333 | Q13: 0.83333333 | R13: 1004 | S13: 1488 | T13: =S13/$T$4 -> 48 | U13: =R13/S13 -> 0.67473118 | V13: 0.83333333 | W13: 973 | X13: 1440 | Y13: =X13/$Y$4 -> 48 | Z13: =W13/X13 -> 0.67569444 | AA13: 0.83333333 | AB13: 932 | AC13: 1488 | AD13: =AB13/AC13 -> 0.62634409 | AE13: 0.83333333 | AF13: 1001 | AG13: 1392 | AH13: =AF13/AG13 -> 0.7191092 | AI13: 0.83333333 | AJ13: 1059 | AK13: 1488 | AL13: =AK13/$AL$4 -> 48 | AM13: 0.71169355 | AN13: 0.83333333 | AO13: =M13+R13+W13+AB13+AF13+AJ13+H13+C13 -> 8345 | AP13: =N13+S13+X13+AC13+AG13+AK13+I13+D13 -> 11712 | AQ13: =AO13/AP13 -> 0.71251708 | AR13: 0.833
A14: Bethany Village | B14: Totals | C14: =C15+C16+C17 -> 16419 | D14: =D15+D16+D17 -> 17360 | E14: =D14/$E$4 -> 560 | F14: =C14/D14 -> 0.94579493 | G14: 0.95192857 | H14: =H15+H16+H17 -> 16541 | I14: =I15+I16+I17 -> 17360 | J14: =I14/$J$4 -> 560 | K14: =H14/I14 -> 0.95282258 | L14: 0.95192857 | M14: =M15+M16+M17 -> 15985 | N14: =N15+N16+N17 -> 16800 | O14: =N14/$O$4 -> 560 | P14: =M14/N14 -> 0.9514881 | Q14: 0.95192857 | R14: =R15+R16+R17 -> 16667 | S14: =S15+S16+S17 -> 17360 | T14: =S14/$T$4 -> 560 | U14: =R14/S14 -> 0.96008065 | V14: 0.95192857 | W14: =W15+W16+W17 -> 16197 | X14: =X15+X16+X17 -> 16800 | Y14: =X14/$Y$4 -> 560 | Z14: =W14/X14 -> 0.96410714 | AA14: 0.95192857 | AB14: 16699 | AC14: 17360 | AD14: 0.96192396 | AE14: 0.95192857 | AF14: 15732 | AG14: 16240 | AH14: 0.96871921 | AI14: 0.95192857 | AJ14: 16689 | AK14: 17360 | AL14: =AK14/$AL$4 -> 560 | AM14: 0.96134793 | AN14: 0.95192857 | AO14: =M14+R14+W14+AB14+AF14+AJ14+H14+C14 -> 130929 | AP14: =N14+S14+X14+AC14+AG14+AK14+I14+D14 -> 136640 | AQ14: =AO14/AP14 -> 0.95820404 | AR14: 0.952
A15: Bethany Village | B15: AL | C15: =3087-124 -> 2963 | D15: 3100 | E15: =D15/$E$4 -> 100 | F15: =C15/D15 -> 0.95580645 | G15: 0.96 | H15: =3111-124 -> 2987 | I15: 3100 | J15: =I15/$J$4 -> 100 | K15: =H15/I15 -> 0.96354839 | L15: 0.96 | M15: =2983-98 -> 2885 | N15: 3000 | O15: =N15/$O$4 -> 100 | P15: =M15/N15 -> 0.96166667 | Q15: 0.96 | R15: 3004 | S15: 3100 | T15: =S15/$T$4 -> 100 | U15: =R15/S15 -> 0.96903226 | V15: 0.96 | W15: 2959 | X15: 3000 | Y15: =X15/$Y$4 -> 100 | Z15: =W15/X15 -> 0.98633333 | AA15: 0.96 | AB15: 3017 | AC15: 3100 | AD15: 0.97322581 | AE15: 0.96 | AF15: 2844 | AG15: 2900 | AH15: 0.98068966 | AI15: 0.96 | AJ15: 2954 | AK15: 3100 | AL15: =AK15/$AL$4 -> 100 | AM15: 0.95290323 | AN15: 0.96 | AO15: =M15+R15+W15+AB15+AF15+AJ15+H15+C15 -> 23613 | AP15: =N15+S15+X15+AC15+AG15+AK15+I15+D15 -> 24400 | AQ15: =AO15/AP15 -> 0.9677459 | AR15: 0.96
A16: Bethany Village | B16: IL | C16: =15084-3549 -> 11535 | D16: 12121 | E16: =D16/$E$4 -> 391 | F16: =C16/D16 -> 0.95165415 | G16: 0.9502046 | H16: 11527 | I16: 12121 | J16: =I16/$J$4 -> 391 | K16: =H16/I16 -> 0.95099414 | L16: 0.9502046 | M16: =11181-30 -> 11151 | N16: 11730 | O16: =N16/$O$4 -> 391 | P16: =M16/N16 -> 0.95063939 | Q16: 0.9502046 | R16: =11647-31 -> 11616 | S16: 12121 | T16: =S16/$T$4 -> 391 | U16: =R16/S16 -> 0.95833677 | V16: 0.9502046 | W16: =11293-30 -> 11263 | X16: 11730 | Y16: =X16/$Y$4 -> 391 | Z16: =W16/X16 -> 0.96018755 | AA16: 0.9502046 | AB16: 11648 | AC16: 12121 | AD16: 0.96097682 | AE16: 0.9502046 | AF16: 10942 | AG16: 11339 | AH16: 0.96498809 | AI16: 0.9502046 | AJ16: 11637 | AK16: 12121 | AL16: =AK16/$AL$4 -> 391 | AM16: 0.9600693 | AN16: 0.9502046 | AO16: =M16+R16+W16+AB16+AF16+AJ16+H16+C16 -> 91319 | AP16: =N16+S16+X16+AC16+AG16+AK16+I16+D16 -> 95404 | AQ16: =AO16/AP16 -> 0.95718209 | AR16: 0.95
A17: Bethany Village | B17: SNF | C17: 1921 | D17: 2139 | E17: =D17/$E$4 -> 69 | F17: =C17/D17 -> 0.89808322 | G17: 0.95 | H17: 2027 | I17: 2139 | J17: =I17/$J$4 -> 69 | K17: =H17/I17 -> 0.94763908 | L17: 0.95 | M17: 1949 | N17: 2070 | O17: =N17/$O$4 -> 69 | P17: =M17/N17 -> 0.94154589 | Q17: 0.95 | R17: 2047 | S17: 2139 | T17: =S17/$T$4 -> 69 | U17: =R17/S17 -> 0.95698925 | V17: 0.95 | W17: 1975 | X17: 2070 | Y17: =X17/$Y$4 -> 69 | Z17: =W17/X17 -> 0.95410628 | AA17: 0.95 | AB17: 2034 | AC17: 2139 | AD17: 0.95091164 | AE17: 0.95 | AF17: 1946 | AG17: 2001 | AH17: 0.97251374 | AI17: 0.95 | AJ17: 2098 | AK17: 2139 | AL17: =AK17/$AL$4 -> 69 | AM17: 0.98083216 | AN17: 0.95 | AO17: =M17+R17+W17+AB17+AF17+AJ17+H17+C17 -> 15997 | AP17: =N17+S17+X17+AC17+AG17+AK17+I17+D17 -> 16836 | AQ17: =AO17/AP17 -> 0.95016631 | AR17: 0.95
A18: Chandler Estates | C18: =2046+1162 -> 3208 | D18: 3286 | E18: =D18/$E$4 -> 106 | F18: =C18/D18 -> 0.97626293 | G18: 0.97169811 | H18: 3233 | I18: 3286 | J18: =I18/$J$4 -> 106 | K18: =H18/I18 -> 0.98387097 | L18: 0.97169811 | M18: 3078 | N18: 3180 | O18: =N18/$O$4 -> 106 | P18: 0.96792453 | Q18: 0.97169811 | R18: 3220 | S18: 3286 | T18: =S18/$T$4 -> 106 | U18: 0.97991479 | V18: 0.97169811 | W18: 3146 | X18: 3180 | Y18: =X18/$Y$4 -> 106 | Z18: 0.98930818 | AA18: 0.97169811 | AB18: 3209 | AC18: 3286 | AD18: 0.97656726 | AE18: 0.97169811 | AF18: 2954 | AG18: 3074 | AH18: 0.96096291 | AI18: 0.97169811 | AJ18: 3097 | AK18: 3286 | AL18: =AK18/$AL$4 -> 106 | AM18: 0.94248326 | AN18: 0.97169811 | AO18: =M18+R18+W18+AB18+AF18+AJ18+H18+C18 -> 25145 | AP18: =N18+S18+X18+AC18+AG18+AK18+I18+D18 -> 25864 | AQ18: =AO18/AP18 -> 0.97220074 | AR18: 0.972
A19: Grace Park | C19: 2750 | D19: 2945 | E19: =D19/$E$4 -> 95 | F19: =C19/D19 -> 0.93378608 | G19: 0.91578947 | H19: 2766 | I19: 2945 | J19: =I19/$J$4 -> 95 | K19: =H19/I19 -> 0.93921902 | L19: 0.91578947 | M19: 2714 | N19: 2850 | O19: =N19/$O$4 -> 95 | P19: 0.9522807 | Q19: 0.91578947 | R19: 2830 | S19: 2945 | T19: =S19/$T$4 -> 95 | U19: 0.96095076 | V19: 0.91578947 | W19: 2746 | X19: 2850 | Y19: =X19/$Y$4 -> 95 | Z19: 0.96350877 | AA19: 0.91578947 | AB19: 2763 | AC19: 2945 | AD19: 0.93820034 | AE19: 0.91578947 | AF19: 2549 | AG19: 2755 | AH19: 0.92522686 | AI19: 0.91578947 | AJ19: 2627 | AK19: 2945 | AL19: =AK19/$AL$4 -> 95 | AM19: 0.89202037 | AN19: 0.91578947 | AO19: =M19+R19+W19+AB19+AF19+AJ19+H19+C19 -> 21745 | AP19: =N19+S19+X19+AC19+AG19+AK19+I19+D19 -> 23180 | AQ19: =AO19/AP19 -> 0.93809318 | AR19: 0.916
A20: Ivy Gables | C20: 1120 | D20: 1612 | E20: =D20/$E$4 -> 52 | F20: =C20/D20 -> 0.69478908 | G20: 0.77980769 | H20: 1056 | I20: 1612 | J20: =I20/$J$4 -> 52 | K20: =H20/I20 -> 0.65508685 | L20: 0.77980769 | M20: 985 | N20: 1560 | O20: =N20/$O$4 -> 52 | P20: 0.63141026 | Q20: 0.77980769 | R20: 1025 | S20: 1612 | T20: =S20/$T$4 -> 52 | U20: 0.63585608 | V20: 0.77980769 | W20: 1040 | X20: 1560 | Y20: =X20/$Y$4 -> 52 | Z20: 0.66666667 | AA20: 0.77980769 | AB20: 1196 | AC20: 1612 | AD20: 0.74193548 | AE20: 0.77980769 | AF20: 1159 | AG20: 1508 | AH20: 0.76856764 | AI20: 0.77980769 | AJ20: 1214 | AK20: 1612 | AL20: =AK20/$AL$4 -> 52 | AM20: 0.75310174 | AN20: 0.77980769 | AO20: =M20+R20+W20+AB20+AF20+AJ20+H20+C20 -> 8795 | AP20: =N20+S20+X20+AC20+AG20+AK20+I20+D20 -> 12688 | AQ20: =AO20/AP20 -> 0.69317465 | AR20: 0.78
A21: Normandie Ridge | B21: Totals | C21: =C22+C23+C24 -> 7306 | D21: =D22+D23+D24 -> 7533 | E21: =D21/$E$4 -> 243 | F21: =C21/D21 -> 0.96986592 | G21: 0.94641975 | H21: =H22+H23+H24 -> 7278 | I21: =I22+I23+I24 -> 7533 | J21: =I21/$J$4 -> 243 | K21: =H21/I21 -> 0.96614894 | L21: 0.94641975 | M21: =M22+M23+M24 -> 7012 | N21: =N22+N23+N24 -> 7290 | O21: =N21/$O$4 -> 243 | P21: =M21/N21 -> 0.96186557 | Q21: 0.94641975 | R21: =R22+R23+R24 -> 7244 | S21: =S22+S23+S24 -> 7533 | T21: =S21/$T$4 -> 243 | U21: =R21/S21 -> 0.96163547 | V21: 0.94641975 | W21: =W22+W23+W24 -> 6908 | X21: =X22+X23+X24 -> 7290 | Y21: =X21/$Y$4 -> 243 | Z21: =W21/X21 -> 0.94759945 | AA21: 0.94641975 | AB21: 7193 | AC21: 7533 | AD21: 0.95486526 | AE21: 0.94641975 | AF21: 6781 | AG21: 7047 | AH21: 0.96225344 | AI21: 0.94641975 | AJ21: 7186 | AK21: 7533 | AL21: =AK21/$AL$4 -> 243 | AM21: 0.95393601 | AN21: 0.94641975 | AO21: =M21+R21+W21+AB21+AF21+AJ21+H21+C21 -> 56908 | AP21: =N21+S21+X21+AC21+AG21+AK21+I21+D21 -> 59292 | AQ21: =AO21/AP21 -> 0.95979221 | AR21: 0.946
A22: Normandie Ridge | B22: AL | C22: =811-62 -> 749 | D22: 775 | E22: =D22/$E$4 -> 25 | F22: =C22/D22 -> 0.96645161 | G22: 0.92 | H22: =758-62 -> 696 | I22: 775 | J22: =I22/$J$4 -> 25 | K22: =H22/I22 -> 0.89806452 | L22: 0.92 | M22: 717 | N22: 750 | O22: =N22/$O$4 -> 25 | P22: =M22/N22 -> 0.956 | Q22: 0.92 | R22: 770 | S22: 775 | T22: =S22/$T$4 -> 25 | U22: =R22/S22 -> 0.99354839 | V22: 0.92 | W22: 710 | X22: 750 | Y22: =X22/$Y$4 -> 25 | Z22: =W22/X22 -> 0.94666667 | AA22: 0.92 | AB22: 709 | AC22: 775 | AD22: 0.91483871 | AE22: 0.92 | AF22: 681 | AG22: 725 | AH22: 0.93931034 | AI22: 0.92 | AJ22: 711 | AK22: 775 | AL22: =AK22/$AL$4 -> 25 | AM22: 0.91741935 | AN22: 0.92 | AO22: =M22+R22+W22+AB22+AF22+AJ22+H22+C22 -> 5743 | AP22: =N22+S22+X22+AC22+AG22+AK22+I22+D22 -> 6100 | AQ22: =AO22/AP22 -> 0.94147541 | AR22: 0.92
A23: Normandie Ridge | B23: IL | C23: =5864-1209 -> 4655 | D23: 4774 | E23: =D23/$E$4 -> 154 | F23: =C23/D23 -> 0.97507331 | G23: 0.95116883 | H23: 4647 | I23: 4774 | J23: =I23/$J$4 -> 154 | K23: =H23/I23 -> 0.97339757 | L23: 0.95116883 | M23: 4436 | N23: 4620 | O23: =N23/$O$4 -> 154 | P23: =M23/N23 -> 0.96017316 | Q23: 0.95116883 | R23: 4560 | S23: 4774 | T23: =S23/$T$4 -> 154 | U23: =R23/S23 -> 0.95517386 | V23: 0.95116883 | W23: 4350 | X23: 4620 | Y23: =X23/$Y$4 -> 154 | Z23: =W23/X23 -> 0.94155844 | AA23: 0.95116883 | AB23: 4580 | AC23: 4774 | AD23: 0.95936322 | AE23: 0.95116883 | AF23: 4272 | AG23: 4466 | AH23: 0.95656068 | AI23: 0.95116883 | AJ23: 4579 | AK23: 4774 | AL23: =AK23/$AL$4 -> 154 | AM23: 0.95915375 | AN23: 0.95116883 | AO23: =M23+R23+W23+AB23+AF23+AJ23+H23+C23 -> 36079 | AP23: =N23+S23+X23+AC23+AG23+AK23+I23+D23 -> 37576 | AQ23: =AO23/AP23 -> 0.96016074 | AR23: 0.951
A24: Normandie Ridge | B24: SNF | C24: 1902 | D24: 1984 | E24: =D24/$E$4 -> 64 | F24: =C24/D24 -> 0.95866935 | G24: 0.9453125 | H24: 1935 | I24: 1984 | J24: =I24/$J$4 -> 64 | K24: =H24/I24 -> 0.97530242 | L24: 0.9453125 | M24: 1859 | N24: 1920 | O24: =N24/$O$4 -> 64 | P24: =M24/N24 -> 0.96822917 | Q24: 0.9453125 | R24: 1914 | S24: 1984 | T24: =S24/$T$4 -> 64 | U24: =R24/S24 -> 0.96471774 | V24: 0.9453125 | W24: 1848 | X24: 1920 | Y24: =X24/$Y$4 -> 64 | Z24: =W24/X24 -> 0.9625 | AA24: 0.9453125 | AB24: 1904 | AC24: 1984 | AD24: 0.95967742 | AE24: 0.9453125 | AF24: 1828 | AG24: 1856 | AH24: 0.98491379 | AI24: 0.9453125 | AJ24: 1896 | AK24: 1984 | AL24: =AK24/$AL$4 -> 64 | AM24: 0.95564516 | AN24: 0.9453125 | AO24: =M24+R24+W24+AB24+AF24+AJ24+H24+C24 -> 15086 | AP24: =N24+S24+X24+AC24+AG24+AK24+I24+D24 -> 15616 | AQ24: =AO24/AP24 -> 0.96606045 | AR24: 0.945
A25: Riverwoods | B25: Totals | C25: =C26+C27+C28 -> 7652 | D25: =D26+D27+D28 -> 8835 | E25: =D25/$E$4 -> 285 | F25: =C25/D25 -> 0.86610074 | G25: 0.86878049 | H25: =H26+H27+H28 -> 7637 | I25: =I26+I27+I28 -> 8835 | J25: =I25/$J$4 -> 285 | K25: =H25/I25 -> 0.86440294 | L25: 0.86878049 | M25: =M26+M27+M28 -> 7362 | N25: =N26+N27+N28 -> 8550 | O25: =N25/$O$4 -> 285 | P25: =M25/N25 -> 0.86105263 | Q25: 0.86878049 | R25: 7577 | S25: 8835 | T25: =S25/$T$4 -> 285 | U25: 0.85761177 | V25: 0.86878049 | W25: 7390 | X25: 8584 | Y25: =X25/$Y$4 -> 286.13333 | Z25: 0.86090401 | AA25: 0.86878049 | AB25: 7806 | AC25: 8897 | AD25: 0.8773744 | AE25: 0.86878049 | AF25: 7264 | AG25: 8323 | AH25: 0.87276223 | AI25: 0.86878049 | AJ25: 7580 | AK25: 8897 | AL25: =AK25/$AL$4 -> 287 | AM25: 0.85197258 | AN25: 0.86878049 | AO25: =M25+R25+W25+AB25+AF25+AJ25+H25+C25 -> 60268 | AP25: =N25+S25+X25+AC25+AG25+AK25+I25+D25 -> 69756 | AQ25: =AO25/AP25 -> 0.86398303 | AR25: 0.869
A26: Riverwoods | B26: AL | C26: =1203-93 -> 1110 | D26: 1178 | E26: =D26/$E$4 -> 38 | F26: =C26/D26 -> 0.94227504 | G26: 0.93 | H26: =1235-93 -> 1142 | I26: 1178 | J26: =I26/$J$4 -> 38 | K26: =H26/I26 -> 0.96943973 | L26: 0.93 | M26: 1044 | N26: 1140 | O26: =N26/$O$4 -> 38 | P26: =M26/N26 -> 0.91578947 | Q26: 0.93 | R26: 1085 | S26: 1178 | T26: =S26/$T$4 -> 38 | U26: 0.92105263 | V26: 0.93 | W26: 1043 | X26: 1140 | Y26: =X26/$Y$4 -> 38 | Z26: 0.91491228 | AA26: 0.93 | AB26: 1159 | AC26: 1178 | AD26: 0.98387097 | AE26: 0.93 | AF26: 1046 | AG26: 1102 | AH26: 0.9491833 | AI26: 0.93 | AJ26: 1054 | AK26: 1178 | AL26: =AK26/$AL$4 -> 38 | AM26: 0.89473684 | AN26: 0.93 | AO26: =M26+R26+W26+AB26+AF26+AJ26+H26+C26 -> 8683 | AP26: =N26+S26+X26+AC26+AG26+AK26+I26+D26 -> 9272 | AQ26: =AO26/AP26 -> 0.93647541 | AR26: 0.93
A27: Riverwoods | B27: IL | C27: =4707-1023 -> 3684 | D27: 3968 | E27: =D27/$E$4 -> 128 | F27: =C27/D27 -> 0.92842742 | G27: 0.93846154 | H27: 3680 | I27: 3968 | J27: =I27/$J$4 -> 128 | K27: =H27/I27 -> 0.92741935 | L27: 0.93846154 | M27: 3581 | N27: =128*30 -> 3840 | O27: =N27/$O$4 -> 128 | P27: =M27/N27 -> 0.93255208 | Q27: 0.93846154 | R27: 3751 | S27: 3968 | T27: =S27/$T$4 -> 128 | U27: 0.9453125 | V27: 0.93846154 | W27: 3660 | X27: 3874 | Y27: =X27/$Y$4 -> 129.13333 | Z27: 0.94475994 | AA27: 0.93846154 | AB27: 3822 | AC27: 4030 | AD27: 0.9483871 | AE27: 0.93846154 | AF27: 3607 | AG27: 3770 | AH27: 0.95676393 | AI27: 0.93846154 | AJ27: 3804 | AK27: 4030 | AL27: =AK27/$AL$4 -> 130 | AM27: 0.9439206 | AN27: 0.93846154 | AO27: =M27+R27+W27+AB27+AF27+AJ27+H27+C27 -> 29589 | AP27: =N27+S27+X27+AC27+AG27+AK27+I27+D27 -> 31448 | AQ27: =AO27/AP27 -> 0.94088654 | AR27: 0.938
A28: Riverwoods | B28: SNF | C28: 2858 | D28: 3689 | E28: =D28/$E$4 -> 119 | F28: =C28/D28 -> 0.7747357 | G28: 0.77310924 | H28: 2815 | I28: 3689 | J28: =I28/$J$4 -> 119 | K28: =H28/I28 -> 0.76307943 | L28: 0.77310924 | M28: 2737 | N28: =119*30 -> 3570 | O28: =N28/$O$4 -> 119 | P28: =M28/N28 -> 0.76666667 | Q28: 0.77310924 | R28: 2741 | S28: 3689 | T28: =S28/$T$4 -> 119 | U28: 0.74301979 | V28: 0.77310924 | W28: 2687 | X28: 3570 | Y28: =X28/$Y$4 -> 119 | Z28: 0.75266106 | AA28: 0.77310924 | AB28: 2825 | AC28: 3689 | AD28: 0.76579019 | AE28: 0.77310924 | AF28: 2611 | AG28: 3451 | AH28: 0.75659229 | AI28: 0.77310924 | AJ28: 2722 | AK28: 3689 | AL28: =AK28/$AL$4 -> 119 | AM28: 0.73786934 | AN28: 0.77310924 | AO28: =M28+R28+W28+AB28+AF28+AJ28+H28+C28 -> 21996 | AP28: =N28+S28+X28+AC28+AG28+AK28+I28+D28 -> 29036 | AQ28: =AO28/AP28 -> 0.75754236 | AR28: 0.773
A29: Springhill | B29: Totals | C29: =C30+C31+C32 -> 7550 | D29: =D30+D31+D32 -> 8401 | E29: =D29/$E$4 -> 271 | F29: =C29/D29 -> 0.89870254 | G29: 0.94796296 | H29: =H30+H31+H32 -> 7555 | I29: =I30+I31+I32 -> 8401 | J29: =I29/$J$4 -> 271 | K29: =H29/I29 -> 0.8992977 | L29: 0.94796296 | M29: =M30+M31+M32 -> 7363 | N29: =N30+N31+N32 -> 8130 | O29: =N29/$O$4 -> 271 | P29: =M29/N29 -> 0.90565806 | Q29: 0.94796296 | R29: 7642 | S29: 8401 | T29: =S29/$T$4 -> 271 | U29: 0.90965361 | V29: 0.94425926 | W29: 7378 | X29: 8130 | Y29: =X29/$Y$4 -> 271 | Z29: 0.90750308 | AA29: 0.94425926 | AB29: 7754 | AC29: 8401 | AD29: 0.92298536 | AE29: 0.94425926 | AF29: 7353 | AG29: 7891 | AH29: 0.93182106 | AI29: 0.94425926 | AJ29: 7791 | AK29: 8494 | AL29: =AK29/$AL$4 -> 274 | AM29: 0.9172357 | AN29: 0.94055556 | AO29: =M29+R29+W29+AB29+AF29+AJ29+H29+C29 -> 60386 | AP29: =N29+S29+X29+AC29+AG29+AK29+I29+D29 -> 66249 | AQ29: =AO29/AP29 -> 0.91150055 | AR29: 0.944
A30: Springhill | B30: AL | C30: 1002 | D30: 1085 | E30: =D30/$E$4 -> 35 | F30: =C30/D30 -> 0.9235023 | G30: 0.96428571 | H30: 1004 | I30: 1085 | J30: =I30/$J$4 -> 35 | K30: =H30/I30 -> 0.92534562 | L30: 0.96428571 | M30: 946 | N30: 1050 | O30: =N30/$O$4 -> 35 | P30: =M30/N30 -> 0.90095238 | Q30: 0.96428571 | R30: 956 | S30: 1085 | T30: =S30/$T$4 -> 35 | U30: 0.88110599 | V30: 0.96428571 | W30: 900 | X30: 1050 | Y30: =X30/$Y$4 -> 35 | Z30: 0.85714286 | AA30: 0.96428571 | AB30: 1028 | AC30: 1085 | AD30: 0.94746544 | AE30: 0.96428571 | AF30: 979 | AG30: 1015 | AH30: 0.96453202 | AI30: 0.96428571 | AJ30: 1056 | AK30: 1085 | AL30: =AK30/$AL$4 -> 35 | AM30: 0.97327189 | AN30: 0.96428571 | AO30: =M30+R30+W30+AB30+AF30+AJ30+H30+C30 -> 7871 | AP30: =N30+S30+X30+AC30+AG30+AK30+I30+D30 -> 8540 | AQ30: =AO30/AP30 -> 0.92166276 | AR30: 0.964
A31: Springhill | B31: IL | C31: =5341-925 -> 4416 | D31: 4929 | E31: =D31/$E$4 -> 159 | F31: =C31/D31 -> 0.89592209 | G31: 0.94339623 | H31: =3415+960 -> 4375 | I31: 4929 | J31: =I31/$J$4 -> 159 | K31: =H31/I31 -> 0.88760398 | L31: 0.94339623 | M31: 4265 | N31: 4770 | O31: =N31/$O$4 -> 159 | P31: =M31/N31 -> 0.89412998 | Q31: 0.94339623 | R31: 4471 | S31: 4929 | T31: =S31/$T$4 -> 159 | U31: 0.90708054 | V31: 0.93710692 | W31: 4298 | X31: 4770 | Y31: =X31/$Y$4 -> 159 | Z31: 0.90104822 | AA31: 0.93710692 | AB31: 4499 | AC31: 4929 | AD31: 0.91276121 | AE31: 0.93710692 | AF31: 4253 | AG31: 4611 | AH31: 0.92235957 | AI31: 0.93710692 | AJ31: 4523 | AK31: 4929 | AL31: =AK31/$AL$4 -> 159 | AM31: 0.91763035 | AN31: 0.93081761 | AO31: =M31+R31+W31+AB31+AF31+AJ31+H31+C31 -> 35100 | AP31: =N31+S31+X31+AC31+AG31+AK31+I31+D31 -> 38796 | AQ31: =AO31/AP31 -> 0.90473245 | AR31: 0.937
A32: Springhill | B32: SNF | C32: 2132 | D32: 2387 | E32: =D32/$E$4 -> 77 | F32: =C32/D32 -> 0.89317134 | G32: 0.95 | H32: 2176 | I32: 2387 | J32: =I32/$J$4 -> 77 | K32: =H32/I32 -> 0.91160452 | L32: 0.95 | M32: 2152 | N32: 2310 | O32: =N32/$O$4 -> 77 | P32: =M32/N32 -> 0.93160173 | Q32: 0.95 | R32: 2215 | S32: 2387 | T32: =S32/$T$4 -> 77 | U32: 0.92794302 | V32: 0.95 | W32: 2180 | X32: 2310 | Y32: =X32/$Y$4 -> 77 | Z32: 0.94372294 | AA32: 0.95 | AB32: 2227 | AC32: 2387 | AD32: 0.93297026 | AE32: 0.95 | AF32: 2121 | AG32: 2265 | AH32: 0.93642384 | AI32: 0.95 | AJ32: 2212 | AK32: 2480 | AL32: =AK32/$AL$4 -> 80 | AM32: 0.89193548 | AN32: 0.95 | AO32: =M32+R32+W32+AB32+AF32+AJ32+H32+C32 -> 17415 | AP32: =N32+S32+X32+AC32+AG32+AK32+I32+D32 -> 18913 | AQ32: =AO32/AP32 -> 0.92079522 | AR32: 0.95
A35: Asbury CCRC | C35: =C6+C10+C14+C21+C25+C29 -> 78943 | D35: =D6+D10+D14+D21+D25+D29 -> 89094 | F35: =C35/D35 -> 0.88606416 | H35: =H6+H10+H14+H21+H25+H29 -> 78923 | I35: =I6+I10+I14+I21+I25+I29 -> 89094 | K35: =H35/I35 -> 0.88583967 | M35: =M6+M10+M14+M21+M25+M29 -> 76257 | N35: =N6+N10+N14+N21+N25+N29 -> 86220 | P35: =M35/N35 -> 0.88444676 | R35: =R6+R10+R14+R21+R25+R29 -> 78659 | S35: =S6+S10+S14+S21+S25+S29 -> 89094 | U35: =R35/S35 -> 0.88287651 | W35: =W6+W10+W14+W21+W25+W29 -> 76732 | X35: =X6+X10+X14+X21+X25+X29 -> 86254 | Z35: =W35/X35 -> 0.88960512 | AB35: =AB6+AB10+AB14+AB21+AB25+AB29 -> 79447 | AC35: =AC6+AC10+AC14+AC21+AC25+AC29 -> 89156 | AD35: =AB35/AC35 -> 0.89110099 | AF35: =AF6+AF10+AF14+AF21+AF25+AF29 -> 74788 | AG35: =AG6+AG10+AG14+AG21+AG25+AG29 -> 83436 | AH35: =AF35/AG35 -> 0.89635169 | AJ35: =AJ6+AJ10+AJ14+AJ21+AJ25+AJ29 -> 79478 | AK35: =AK6+AK10+AK14+AK21+AK25+AK29 -> 89249 | AM35: =AJ35/AK35 -> 0.89051978 | AO35: =AO6+AO10+AO14+AO21+AO25+AO29 -> 623227 | AP35: =AP6+AP10+AP14+AP21+AP25+AP29 -> 701597 | AQ35: =AO35/AP35 -> 0.8882977
A37: Asbury CCRC + CE | C37: =C6+C10+C14+C18+C21+C25+C29 -> 82151 | D37: =D6+D10+D14+D18+D21+D25+D29 -> 92380 | F37: =C37/D37 -> 0.88927257 | H37: =H6+H10+H14+H18+H21+H25+H29 -> 82156 | I37: =I6+I10+I14+I18+I21+I25+I29 -> 92380 | K37: =H37/I37 -> 0.88932669 | M37: =M6+M10+M14+M18+M21+M25+M29 -> 79335 | N37: =N6+N10+N14+N18+N21+N25+N29 -> 89400 | P37: =M37/N37 -> 0.88741611 | R37: =R6+R10+R14+R18+R21+R25+R29 -> 81879 | S37: =S6+S10+S14+S18+S21+S25+S29 -> 92380 | U37: =R37/S37 -> 0.88632821 | W37: =W6+W10+W14+W18+W21+W25+W29 -> 79878 | X37: =X6+X10+X14+X18+X21+X25+X29 -> 89434 | Z37: =W37/X37 -> 0.89315026 | AB37: =AB6+AB10+AB14+AB18+AB21+AB25+AB29 -> 82656 | AC37: =AC6+AC10+AC14+AC18+AC21+AC25+AC29 -> 92442 | AD37: =AB37/AC37 -> 0.89413903 | AF37: =AF6+AF10+AF14+AF18+AF21+AF25+AF29 -> 77742 | AG37: =AG6+AG10+AG14+AG18+AG21+AG25+AG29 -> 86510 | AH37: =AF37/AG37 -> 0.89864756 | AJ37: =AJ6+AJ10+AJ14+AJ18+AJ21+AJ25+AJ29 -> 82575 | AK37: =AK6+AK10+AK14+AK18+AK21+AK25+AK29 -> 92535 | AM37: =AJ37/AK37 -> 0.89236505 | AO37: =AO6+AO10+AO14+AO18+AO21+AO25+AO29 -> 648372 | AP37: =AP6+AP10+AP14+AP18+AP21+AP25+AP29 -> 727461 | AQ37: =AO37/AP37 -> 0.89128077
A39: Asbury Living | C39: =C19+C20 -> 3870 | D39: =D19+D20 -> 4557 | F39: =C39/D39 -> 0.84924292 | H39: =H19+H20 -> 3822 | I39: =I19+I20 -> 4557 | K39: =H39/I39 -> 0.83870968 | M39: =M19+M20 -> 3699 | N39: =N19+N20 -> 4410 | P39: =M39/N39 -> 0.83877551 | R39: =R19+R20 -> 3855 | S39: =S19+S20 -> 4557 | U39: =R39/S39 -> 0.84595128 | W39: =W19+W20 -> 3786 | X39: =X19+X20 -> 4410 | Z39: =W39/X39 -> 0.8585034 | AB39: =AB19+AB20 -> 3959 | AC39: =AC19+AC20 -> 4557 | AD39: =AB39/AC39 -> 0.86877332 | AF39: =AF19+AF20 -> 3708 | AG39: =AG19+AG20 -> 4263 | AH39: =AF39/AG39 -> 0.86980999 | AJ39: =AJ19+AJ20 -> 3841 | AK39: =AK19+AK20 -> 4557 | AM39: =AJ39/AK39 -> 0.84287909 | AO39: =AO19+AO20 -> 30540 | AP39: =AP19+AP20 -> 35868 | AQ39: =AO39/AP39 -> 0.85145534
A41: TOTAL | C41: =C37+C39 -> 86021 | D41: =D37+D39 -> 96937 | F41: =C41/D41 -> 0.88739078 | H41: =H37+H39 -> 85978 | I41: =I37+I39 -> 96937 | K41: =H41/I41 -> 0.88694719 | M41: =M37+M39 -> 83034 | N41: =N37+N39 -> 93810 | P41: =M41/N41 -> 0.88512952 | R41: =R37+R39 -> 85734 | S41: =S37+S39 -> 96937 | U41: =R41/S41 -> 0.88443009 | W41: =W37+W39 -> 83664 | X41: =X37+X39 -> 93844 | Z41: =W41/X41 -> 0.8915221 | AB41: =AB37+AB39 -> 86615 | AC41: =AC37+AC39 -> 96999 | AD41: =AB41/AC41 -> 0.89294735 | AF41: =AF37+AF39 -> 81450 | AG41: =AG37+AG39 -> 90773 | AH41: =AF41/AG41 -> 0.89729325 | AJ41: =AJ37+AJ39 -> 86416 | AK41: =AK37+AK39 -> 97092 | AM41: =AJ41/AK41 -> 0.89004243 | AO41: =AO37+AO39 -> 678912 | AP41: =AP37+AP39 -> 763329 | AQ41: =AO41/AP41 -> 0.88940942
A43: CHECK | C43: =C5-C41 -> 0 | D43: =D5-D41 -> 0 | F43: =F5-F41 -> 0 | H43: =H5-H41 -> 0 | I43: =I5-I41 -> 0 | K43: =K5-K41 -> 0 | M43: =M5-M41 -> 0 | N43: =N5-N41 -> 0 | P43: =P5-P41 -> 0 | R43: =R5-R41 -> 0 | S43: =S5-S41 -> 0 | U43: =U5-U41 -> 0 | W43: =W5-W41 -> 0 | X43: =X5-X41 -> 0 | Z43: =Z5-Z41 -> 0 | AB43: =AB5-AB41 -> 0 | AC43: =AC5-AC41 -> 0 | AD43: =AE5-AD41 -> 0.0080884557 | AF43: =AF5-AF41 -> 0 | AG43: =AG5-AG41 -> 0 | AH43: =AI5-AH41 -> 0.0029433249 | AJ43: =AJ5-AJ41 -> 0 | AK43: =AK5-AK41 -> 0 | AM43: =AM5-AM41 -> 0 | AO43: =AO5-AO41 -> 0 | AP43: =AP5-AP41 -> 0 | AQ43: =AR5-AQ41 -> 0.011590584

Sheet Occupancy Level 
A1: RL | B1: Year | C1: 2024 | D1: 2024 | E1: 2024 | F1: 2024
B2: Year-Quarter | C2: YTD
B3: CampusName | C3: Resident Days | D3: In Service Days | E3: Occupancy % | F3: Budget Occupancy % | I3: Actual | J3: In Service | K3: Occ% | N3: CHECK
B4: Totals | C4: =SUM(C5:C12) -> 439114 | D4: =SUM(D5:D12) -> 497244 | E4: =C4/D4 -> 0.88309562 | F4: 0.895 | H4: Asbury CCRC | I4: =C5+C6+C7+C8+C10+C11+C12 -> 436013 | J4: =D5+D6+D7+D8+D10+D11+D12 -> 494072 | K4: =I4/J4 -> 0.88248879 | N4: Level | O4: =C4+C18+C33 -> 678912 | P4: =D4+D18+D33 -> 763329 | Q4: =O4/P4 -> 0.88940942
B5: Asbury Methodist Village | C5: =Occupancy!AO8 -> 157952 | D5: =Occupancy!AP8 -> 201300 | E5: =C5/D5 -> 0.78465971 | F5: 0.819 | N5: Occupnacy | O5: =Occupancy!AO5 -> 678912 | P5: =Occupancy!AP5 -> 763329 | Q5: =O5/P5 -> 0.88940942
B6: Asbury Solomons | C6: =Occupancy!AO12 -> 69841 | D6: =Occupancy!AP12 -> 73200 | E6: =C6/D6 -> 0.95411202 | F6: 0.942 | H6: Asbury Living | I6: =C9 -> 3101 | J6: =D9 -> 3172 | K6: =I6/J6 -> 0.97761665 | O6: =O4-O5 -> 0 | P6: =P4-P5 -> 0 | Q6: =Q4-Q5 -> 0
B7: Bethany Village | C7: =Occupancy!AO16 -> 91319 | D7: =Occupancy!AP16 -> 95404 | E7: =C7/D7 -> 0.95718209 | F7: 0.95
B8: Chandler Estates | C8: =14087+2511-465 -> 16133 | D8: =14271+2077 -> 16348 | E8: =C8/D8 -> 0.98684854 | F8: 0.97 | H8: TOTAL | I8: =SUM(I4:I6) -> 439114 | J8: =SUM(J4:J6) -> 497244 | K8: =I8/J8 -> 0.88309562
B9: Grace Park | C9: 3101 | D9: 3172 | E9: =C9/D9 -> 0.97761665 | F9: 0.96
B10: Normandie Ridge | C10: =Occupancy!AO23 -> 36079 | D10: =Occupancy!AP23 -> 37576 | E10: =C10/D10 -> 0.96016074 | F10: 0.951 | H10: Check | I10: =C4-I8 -> 0 | J10: =D4-J8 -> 0 | K10: =E4-K8 -> 0
B11: Riverwoods | C11: =Occupancy!AO27 -> 29589 | D11: =Occupancy!AP27 -> 31448 | E11: =C11/D11 -> 0.94088654 | F11: 0.938
B12: Springhill | C12: =Occupancy!AO31 -> 35100 | D12: =Occupancy!AP31 -> 38796 | E12: =C12/D12 -> 0.90473245 | F12: 0.937
A15: AL | B15: Year | C15: 2024 | D15: 2024 | E15: 2024 | F15: 2024
B16: Year-Quarter | C16: YTD
B17: CampusName | C17: Resident Days | D17: In Service Days | E17: Occupancy % | F17: Budget Occupancy %
B18: Totals | C18: =SUM(C19:C27) -> 117181 | D18: =SUM(D19:D27) -> 128832 | E18: =C18/D18 -> 0.90956439 | F18: 0.92 | H18: Asbury CCRC | I18: =C19+C20+C21+C22+C25+C26+C27 -> 89742 | J18: =D19+D20+D21+D22+D25+D26+D27 -> 96136 | K18: =I18/J18 -> 0.93349006
B19: Asbury Methodist Village | C19: =Occupancy!AO7 -> 29022 | D19: =Occupancy!AP7 -> 32452 | E19: =C19/D19 -> 0.89430544 | F19: 0.91
B20: Asbury Solomons | C20: =Occupancy!AO11 -> 5798 | D20: =Occupancy!AP11 -> 5856 | E20: =C20/D20 -> 0.99009563 | F20: 0.98 | H20: Asbury Living | I20: =C23+C24 -> 27439 | J20: =D23+D24 -> 32696 | K20: =I20/J20 -> 0.83921581
B21: Bethany Village | C21: =Occupancy!AO15 -> 23613 | D21: =Occupancy!AP15 -> 24400 | E21: =C21/D21 -> 0.9677459 | F21: 0.96
B22: Chandler Estates | C22: =7850+1199-37 -> 9012 | D22: =8307+1209 -> 9516 | E22: =C22/D22 -> 0.94703657 | F22: 0.974 | H22: TOTAL | I22: =SUM(I18:I20) -> 117181 | J22: =SUM(J18:J20) -> 128832 | K22: =I22/J22 -> 0.90956439
B23: Grace Park | C23: 18644 | D23: =17466+2542 -> 20008 | E23: =C23/D23 -> 0.93182727 | F23: 0.909
B24: Ivy Gables | C24: 8795 | D24: =11076+1612 -> 12688 | E24: =C24/D24 -> 0.69317465 | F24: 0.78 | H24: Check | I24: =C18-I22 -> 0 | J24: =D18-J22 -> 0 | K24: =E18-K22 -> 0
B25: Normandie Ridge | C25: =Occupancy!AO22 -> 5743 | D25: =Occupancy!AP22 -> 6100 | E25: =C25/D25 -> 0.94147541 | F25: 0.92
B26: Riverwoods | C26: =Occupancy!AO26 -> 8683 | D26: =Occupancy!AP26 -> 9272 | E26: =C26/D26 -> 0.93647541 | F26: 0.93
B27: Springhill | C27: =Occupancy!AO30 -> 7871 | D27: =Occupancy!AP30 -> 8540 | E27: =C27/D27 -> 0.92166276 | F27: 0.964
A30: SNF | B30: Year | C30: 2024 | D30: 2024 | E30: 2024 | F30: 2024
B31: Year-Quarter | C31: YTD
B32: CampusName | C32: Resident Days | D32: In Service Days | E32: Occupancy % | F32: Budget Occupancy %
B33: Totals | C33: =SUM(C34:C39) -> 122617 | D33: =SUM(D34:D39) -> 137253 | E33: =C33/D33 -> 0.89336481 | F33: 0.905 | H33: Asbury CCRC | I33: =C34+C35+C36+C37+C38+C39 -> 122617 | J33: =D34+D35+D36+D37+D38+D39 -> 137253 | K33: =I33/J33 -> 0.89336481
B34: Asbury Methodist Village | C34: =Occupancy!AO9 -> 43778 | D34: =Occupancy!AP9 -> 45140 | E34: =C34/D34 -> 0.9698272 | F34: 0.958
B35: Asbury Solomons | C35: =Occupancy!AO13 -> 8345 | D35: =Occupancy!AP13 -> 11712 | E35: =C35/D35 -> 0.71251708 | F35: 0.833 | H35: Asbury Living | I35: 0 | J35: 0
B36: Bethany Village | C36: =Occupancy!AO17 -> 15997 | D36: =Occupancy!AP17 -> 16836 | E36: =C36/D36 -> 0.95016631 | F36: 0.95
B37: Normandie Ridge | C37: =Occupancy!AO24 -> 15086 | D37: =Occupancy!AP24 -> 15616 | E37: =C37/D37 -> 0.96606045 | F37: 0.945 | H37: TOTAL | I37: =SUM(I33:I35) -> 122617 | J37: =SUM(J33:J35) -> 137253 | K37: =I37/J37 -> 0.89336481
B38: Riverwoods | C38: =Occupancy!AO28 -> 21996 | D38: =Occupancy!AP28 -> 29036 | E38: =C38/D38 -> 0.75754236 | F38: 0.773
B39: Springhill | C39: =Occupancy!AO32 -> 17415 | D39: =Occupancy!AP32 -> 18913 | E39: =C39/D39 -> 0.92079522 | F39: 0.95 | H39: Check | I39: =C33-I37 -> 0 | J39: =D33-J37 -> 0 | K39: =E33-K37 -> 0

Sheet SNF Payer Mix
B1: Year | M1: 2024 | N1: 2024 | O1: 2024 | P1: 2024 | Q1: 2024 | R1: 2024 | S1: 2024 | T1: 2024 | U1: 2024 | V1: 2024 | W1: 2024 | X1: 2024 | Y1: 2024 | Z1: 2024 | AA1: 2024 | AB1: 2024 | AC1: 2024 | AD1: 2024 | AE1: 2024 | AF1: 2024 | AG1: 2024 | AH1: 2024 | AI1: 2024 | AJ1: 2024 | AK1: 2024 | AL1: 2024 | AM1: 2024 | AN1: 2024 | AO1: 2024 | AP1: 2024
B2: Year-Quarter | M2: 2024-Q2 | N2: 2024-Q2 | O2: 2024-Q2 | P2: 2024-Q2 | Q2: 2024-Q2 | R2: 2024-Q2 | S2: 2024-Q2 | T2: 2024-Q2 | U2: 2024-Q2 | V2: 2024-Q2 | W2: 2024-Q2 | X2: 2024-Q2 | Y2: 2024-Q2 | Z2: 2024-Q2 | AA2: 2024-Q2 | AB2: 2024-Q1 | AC2: 2024-Q1 | AD2: 2024-Q1 | AE2: 2024-Q1 | AF2: 2024-Q1 | AG2: 2024-Q1 | AH2: 2024-Q1 | AI2: 2024-Q1 | AJ2: 2024-Q1 | AK2: 2024-Q1 | AL2: 2024-Q1 | AM2: 2024-Q1 | AN2: 2024-Q1 | AO2: 2024-Q1 | AP2: 2024-Q1
B3: Year-Month | C3: 2024-Aug | D3: 2024-Jun | E3: 2024-Jun | F3: 2024-Jun | G3: 2024-Jun | H3: 2024-July | I3: 2024-Jun | J3: 2024-Jun | K3: 2024-Jun | L3: 2024-Jun | M3: 2024-Jun | N3: 2024-Jun | O3: 2024-Jun | P3: 2024-Jun | Q3: 2024-Jun | R3: 2024-May | S3: 2024-May | T3: 2024-May | U3: 2024-May | V3: 2024-May | W3: 2024-Apr | X3: 2024-Apr | Y3: 2024-Apr | Z3: 2024-Apr | AA3: 2024-Apr | AB3: 2024-Mar | AC3: 2024-Mar | AD3: 2024-Mar | AE3: 2024-Mar | AF3: 2024-Mar | AG3: 2024-Feb | AH3: 2024-Feb | AI3: 2024-Feb | AJ3: 2024-Feb | AK3: 2024-Feb | AL3: 2024-Jan | AM3: 2024-Jan | AN3: 2024-Jan | AO3: 2024-Jan | AP3: 2024-Jan | AQ3: 2024 YTD SNF Payer Mix
B4: Date | C4: Totals | D4: Totals | E4: Totals | F4: Totals | G4: Totals | H4: Totals | I4: Totals | J4: Totals | K4: Totals | L4: Totals | M4: Totals | N4: Totals | O4: Totals | P4: Totals | Q4: Totals | R4: Totals | S4: Totals | T4: Totals | U4: Totals | V4: Totals | W4: Totals | X4: Totals | Y4: Totals | Z4: Totals | AA4: Totals | AB4: Totals | AC4: Totals | AD4: Totals | AE4: Totals | AF4: Totals | AG4: Totals | AH4: Totals | AI4: Totals | AJ4: Totals | AK4: Totals | AL4: Totals | AM4: Totals | AN4: Totals | AO4: Totals | AP4: Totals
A5: Campus Name | B5: Payer Name | C5: Resident Days | D5: Budget Resident Days | E5: Variance | F5: Payer Mix | G5: Budget Payer Mix | H5: Resident Days | I5: Budget Resident Days | J5: Variance | K5: Payer Mix | L5: Budget Payer Mix | M5: Resident Days | N5: Budget Resident Days | O5: Variance | P5: Payer Mix | Q5: Budget Payer Mix | R5: Resident Days | S5: Budget Resident Days | T5: Variance | U5: Payer Mix | V5: Budget Payer Mix | W5: Resident Days | X5: Budget Resident Days | Y5: Variance | Z5: Payer Mix | AA5: Budget Payer Mix | AB5: Resident Days | AC5: Budget Resident Days | AD5: Variance | AE5: Payer Mix | AF5: Budget Payer Mix | AG5: Resident Days | AH5: Budget Resident Days | AI5: Variance | AJ5: Payer Mix | AK5: Budget Payer Mix | AL5: Resident Days | AM5: Budget Resident Days | AN5: Variance | AO5: Payer Mix | AP5: Budget Payer Mix | AQ5: Resident Days | AR5: Budget Resident Days | AS5: Variance | AT5: Payer Mix | AU5: Budget Payer Mix
A6: Totals | C6: =C7+C15+C22+C28+C35+C42 -> 15649 | D6: =D7+D15+D22+D28+D35+D42 -> 15688 | E6: =C6-D6 -> -39 | F6: 1 | G6: 1 | H6: =H7+H15+H22+H28+H35+H42 -> 15607 | I6: =I7+I15+I22+I28+I35+I42 -> 15690 | J6: =H6-I6 -> -83 | K6: 1 | L6: 1 | M6: =M7+M15+M22+M28+M35+M42 -> 15139 | N6: =N7+N15+N22+N28+N35+N42 -> 15247.2 | O6: =M6-N6 -> -108.2 | P6: 1 | Q6: 1 | R6: =R7+R15+R22+R28+R35+R42 -> 15239 | S6: =S7+S15+S22+S28+S35+S42 -> 15755.44 | T6: =R6-S6 -> -516.44 | U6: 1 | V6: 1 | W6: =W7+W15+W22+W28+W35+W42 -> 15224 | X6: =X7+X15+X22+X28+X35+X42 -> 15247.2 | Y6: =W6-X6 -> -23.2 | Z6: 1 | AA6: 1 | AB6: =AB7+AB15+AB22+AB28+AB35+AB42 -> 15592 | AC6: =AC7+AC15+AC22+AC28+AC35+AC42 -> 15755.44 | AD6: =AB6-AC6 -> -163.44 | AE6: 1 | AF6: 1 | AG6: =AG7+AG15+AG22+AG28+AG35+AG42 -> 14795 | AH6: =AH7+AH15+AH22+AH28+AH35+AH42 -> 14738.96 | AI6: =AG6-AH6 -> 56.04 | AJ6: 1 | AK6: 1 | AL6: =AL7+AL15+AL22+AL28+AL35+AL42 -> 15372 | AM6: =AM7+AM15+AM22+AM28+AM35+AM42 -> 15755.44 | AN6: =AL6-AM6 -> -383.44 | AO6: 1 | AP6: 1 | AQ6: =M6+R6+W6+AB6+AG6+AL6+H6+C6 -> 122617 | AR6: =N6+S6+X6+AC6+AH6+AM6+I6+D6 -> 123877.68 | AS6: =AQ6-AR6 -> -1260.68 | AT6: =AQ6/AQ6 -> 1 | AX6: TOTAL YTD | BD6: Q1 2024 | BJ6: Q2 2024 | BP6: Q3 2024
A7: Asbury Methodist Village | B7: Totals | C7: =SUM(C8:C14) -> 5589 | D7: =SUM(D8:D14) -> 5518 | E7: =C7-D7 -> 71 | F7: 1 | G7: 1 | H7: =SUM(H8:H14) -> 5563 | I7: =SUM(I8:I14) -> 5518 | J7: =H7-I7 -> 45 | K7: 1 | L7: 1 | M7: =SUM(M8:M14) -> 5404 | N7: =SUM(N8:N14) -> 5340 | O7: =M7-N7 -> 64 | P7: 1 | Q7: 1 | R7: 5318 | S7: 5518 | T7: -200 | U7: 1 | V7: 1 | W7: 5561 | X7: 5340 | Y7: 221 | Z7: 1 | AA7: 1 | AB7: 5670 | AC7: 5518 | AD7: 152 | AE7: 1 | AF7: 1 | AG7: 5288 | AH7: 5162 | AI7: 126 | AJ7: 1 | AK7: 1 | AL7: 5385 | AM7: 5518 | AN7: -133 | AO7: 1 | AP7: 1 | AQ7: =M7+R7+W7+AB7+AG7+AL7+H7+C7 -> 43778 | AR7: =N7+S7+X7+AC7+AH7+AM7+I7+D7 -> 43432 | AS7: =AQ7-AR7 -> 346 | AT7: =AQ7/AQ7 -> 1 | AX7: Total by payer | BD7: Total by payer | BI7: AMV | BJ7: Total by payer | BO7: AMV | BP7: Total by payer
A8: Asbury Methodist Village | B8: Hospice | C8: =23+45 -> 68 | D8: 85 | E8: =C8-D8 -> -17 | F8: =C8/$H$7 -> 0.01222362 | G8: 0.015449438 | H8: 57 | I8: 85 | J8: =H8-I8 -> -28 | K8: =H8/$H$7 -> 0.01024627 | L8: 0.015449438 | M8: 46 | N8: 82.5 | O8: -36.5 | P8: 0.0084980602 | Q8: 0.015449438 | R8: 70 | S8: 85.25 | T8: -15.25 | U8: 0.013162843 | V8: 0.015449438 | W8: 100 | X8: 82.5 | Y8: 17.5 | Z8: 0.017982377 | AA8: 0.015449438 | AB8: 140 | AC8: 85.25 | AD8: 54.75 | AE8: 0.024691358 | AF8: 0.015449438 | AG8: 129 | AH8: 79.75 | AI8: 49.25 | AJ8: 0.024394856 | AK8: 0.015449438 | AL8: 124 | AM8: 85.25 | AN8: 38.75 | AO8: 0.023026927 | AP8: 0.015449438 | AQ8: =M8+R8+W8+AB8+AG8+AL8+H8+C8 -> 734 | AR8: =N8+S8+X8+AC8+AH8+AM8+I8+D8 -> 670.5 | AS8: =AQ8-AR8 -> 63.5 | AT8: =AQ8/AQ7 -> 0.016766412 | AY8: Actual | AZ8: Budget | BA8: Actual | BB8: Budget | BE8: Actual | BF8: Budget | BG8: Actual | BH8: Budget | BK8: Actual | BL8: Budget | BM8: Actual | BN8: Budget | BQ8: Actual | BR8: Budget | BS8: Actual | BT8: Budget
A9: Asbury Methodist Village | B9: Managed Care | C9: =19+7+12+23+2 -> 63 | D9: 57 | E9: =C9-D9 -> 6 | F9: =C9/$H$7 -> 0.011324825 | G9: 0.010337079 | H9: 28 | I9: 57 | J9: =H9-I9 -> -29 | K9: =H9/$H$7 -> 0.0050332554 | L9: 0.010337079 | M9: 84 | N9: 55.2 | O9: 18.8 | P9: 0.013670793 | Q9: 0.010337079 | R9: 106 | S9: 57.04 | T9: 48.96 | U9: 0.019932305 | V9: 0.010337079 | W9: 164 | X9: 55.2 | Y9: 108.8 | Z9: 0.029491099 | AA9: 0.010337079 | AB9: 143 | AC9: 57.04 | AD9: 85.96 | AE9: 0.025220459 | AF9: 0.010337079 | AG9: 74 | AH9: 53.36 | AI9: 20.64 | AJ9: 0.013993949 | AK9: 0.010337079 | AL9: 41 | AM9: 57.04 | AN9: -16.04 | AO9: 0.0076137419 | AP9: 0.010337079 | AQ9: =M9+R9+W9+AB9+AG9+AL9+H9+C9 -> 703 | AR9: =N9+S9+X9+AC9+AH9+AM9+I9+D9 -> 448.88 | AS9: =AQ9-AR9 -> 254.12 | AT9: =AQ9/AQ7 -> 0.016058294 | AX9: Hospice | AY9: =BK98 -> 734 | AZ9: =BL98 -> 670.5 | BA9: =AY9/AY16 -> 0.0059861194 | BB9: =AZ9/AZ16 -> 0.0054125973 | BD9: Hospice | BE9: =AB8+AG8+AL8 -> 393 | BF9: =AC8+AH8+AM8 -> 250.25 | BG9: =BE9/BE16 -> 0.024046993 | BH9: =BF9/BF16 -> 0.015449438 | BJ9: Hospice | BK9: =M8+R8+W8 -> 216 | BL9: =N8+S8+X8 -> 250.25 | BM9: =BK9/BK16 -> 0.013265369 | BN9: =BL9/BL16 -> 0.015449438 | BP9: Hospice | BQ9: =C8+H8 -> 125 | BR9: =D8+I8 -> 170 | BS9: =BQ9/BQ16 -> 0.011208752 | BT9: =BR9/BR16 -> 0.015404132 | BW9: =BE9+BK9+BQ9 -> 734
A10: Asbury Methodist Village | B10: Medicaid | C10: =2509+1 -> 2510 | D10: 2848 | E10: =C10-D10 -> -338 | F10: =C10/$H$7 -> 0.4511954 | G10: 0.51617978 | H10: 2511 | I10: 2848 | J10: =H10-I10 -> -337 | K10: =H10/$H$7 -> 0.45137516 | L10: 0.51617978 | M10: 2343 | N10: 2756.4 | O10: -522.4 | P10: 0.41271014 | Q10: 0.51617978 | R10: 2392 | S10: 2848.28 | T10: -518.28 | U10: 0.43813464 | V10: 0.51617978 | W10: 2156 | X10: 2757 | Y10: -601 | Z10: 0.38770005 | AA10: 0.51629213 | AB10: 2234 | AC10: 2848.9 | AD10: -614.9 | AE10: 0.39400353 | AF10: 0.51629213 | AG10: 2068 | AH10: 2665.1 | AI10: -597.1 | AJ10: 0.39107413 | AK10: 0.51629213 | AL10: 2181 | AM10: 2820.69 | AN10: -639.69 | AO10: 0.40501393 | AP10: 0.51117978 | AQ10: =M10+R10+W10+AB10+AG10+AL10+H10+C10 -> 18395 | AR10: =N10+S10+X10+AC10+AH10+AM10+I10+D10 -> 22392.37 | AS10: =AQ10-AR10 -> -3997.37 | AT10: =AQ10/AQ7 -> 0.42018822 | AX10: Managed Care | AY10: =BK99 -> 1355 | AZ10: =BL99 -> 1352.28 | BA10: =AY10/AY16 -> 0.01105067 | BB10: =AZ10/AZ16 -> 0.010916252 | BD10: Managed Care | BE10: =AB9+AG9+AL9 -> 258 | BF10: =AC9+AH9+AM9 -> 167.44 | BG10: =BE10/BE16 -> 0.015786575 | BH10: =BF10/BF16 -> 0.010337079 | BJ10: Managed Care | BK10: =M9+R9+W9 -> 354 | BL10: =N9+S9+X9 -> 167.44 | BM10: =BK10/BK16 -> 0.021740466 | BN10: =BL10/BL16 -> 0.010337079 | BP10: Managed Care | BQ10: =C9+H9 -> 91 | BR10: =D9+I9 -> 114 | BS10: =BQ10/BQ16 -> 0.0081599713 | BT10: =BR10/BR16 -> 0.01032983 | BW10: =BE10+BK10+BQ10 -> 703
A11: Asbury Methodist Village | B11: Medicaid Pending | C11: 155 | D11: 0 | E11: =C11-D11 -> 155 | F11: =C11/$H$7 -> 0.027862664 | G11: 0 | H11: 201 | I11: 0 | J11: =H11-I11 -> 201 | K11: =H11/$H$7 -> 0.036131584 | L11: 0 | M11: 126 | N11: 0 | O11: 236 | P11: 0.043598744 | Q11: 0 | R11: 85 | S11: 0 | T11: 147 | U11: 0.027641971 | V11: 0 | W11: 0 | X11: 0 | Y11: 0 | Z11: 0 | AA11: 0 | AB11: 0 | AC11: 0 | AD11: 0 | AE11: 0 | AF11: 0 | AG11: 0 | AH11: 0 | AI11: 0 | AJ11: 0 | AK11: 0 | AL11: 0 | AM11: 0 | AN11: 0 | AO11: 0 | AP11: 0 | AQ11: =M11+R11+W11+AB11+AG11+AL11+H11+C11 -> 567 | AR11: =N11+S11+X11+AC11+AH11+AM11+I11+D11 -> 0 | AS11: =AQ11-AR11 -> 567 | AT11: =AQ11/AQ7 -> 0.012951711 | AX11: Medicaid | AY11: =BK100 -> 53313 | AZ11: =BL100 -> 58322.69 | BA11: =AY11/AY16 -> 0.43479289 | BB11: =AZ11/AZ16 -> 0.4708087 | BD11: Medicaid | BE11: =AB10+AG10+AL10 -> 6483 | BF11: =AC10+AH10+AM10 -> 8334.69 | BG11: =BE11/BE16 -> 0.3966836 | BH11: =BF11/BF16 -> 0.51455056 | BJ11: Medicaid | BK11: =M10+R10+W10 -> 6891 | BL11: =N10+S10+X10 -> 8361.68 | BM11: =BK11/BK16 -> 0.42320211 | BN11: =BL11/BL16 -> 0.51621682 | BP11: Medicaid | BQ11: =C10+H10 -> 5021 | BR11: =D10+I10 -> 5696 | BS11: =BQ11/BQ16 -> 0.45023314 | BT11: =BR11/BR16 -> 0.51612903 | BW11: =BE11+BK11+BQ11 -> 18395
A12: Asbury Methodist Village | B12: Medicare Advantage | C12: =42+6+31+33+32+30+13 -> 187 | D12: 221 | E12: =C12-D12 -> -34 | F12: =C12/$H$7 -> 0.033614956 | G12: 0.04 | H12: 410 | I12: 221 | J12: =H12-I12 -> 189 | K12: =H12/$H$7 -> 0.07370124 | L12: 0.04 | M12: 399 | N12: 213.6 | O12: 194.4 | P12: 0.075374099 | Q12: 0.04 | R12: 350 | S12: 220.72 | T12: 129.28 | U12: 0.065814216 | V12: 0.04 | W12: 464 | X12: 216.6 | Y12: 247.4 | Z12: 0.083438231 | AA12: 0.040561798 | AB12: 459 | AC12: 226.92 | AD12: 232.08 | AE12: 0.080952381 | AF12: 0.041123596 | AG12: 406 | AH12: 215.18 | AI12: 190.82 | AJ12: 0.07677761 | AK12: 0.041685393 | AL12: 391 | AM12: 233.12 | AN12: 157.88 | AO12: 0.072609099 | AP12: 0.042247191 | AQ12: =M12+R12+W12+AB12+AG12+AL12+H12+C12 -> 3066 | AR12: =N12+S12+X12+AC12+AH12+AM12+I12+D12 -> 1768.14 | AS12: =AQ12-AR12 -> 1297.86 | AT12: =AQ12/AQ7 -> 0.070035177 | AX12: Medicaid Pending | AY12: =BK101 -> 1958 | AZ12: =BL101 -> 0 | BA12: =AY12/AY16 -> 0.015968422 | BB12: =AZ12/AZ16 -> 0 | BD12: Medicaid Pending | BE12: =AB11+AG11+AL11 -> 0 | BF12: =AC11+AH11+AM11 -> 0 | BG12: =BE12/BE16 -> 0 | BH12: =BF12/BF16 -> 0 | BJ12: Medicaid Pending | BK12: =M11+R11+W11 -> 211 | BL12: =N11+S11+X11 -> 0 | BM12: =BK12/BK16 -> 0.0129583 | BN12: =BL12/BL16 -> 0 | BP12: Medicaid Pending | BQ12: =C11+H11 -> 356 | BR12: =D11+I11 -> 0 | BS12: =BQ12/BQ16 -> 0.031922525 | BT12: =BR12/BR16 -> 0 | BW12: =BE12+BK12+BQ12 -> 567
A13: Asbury Methodist Village | B13: MedicareA/MC HMO | C13: =277+1045 -> 1322 | D13: 883 | E13: =C13-D13 -> 439 | F13: =C13/$H$7 -> 0.23764156 | G13: 0.16 | H13: 1088 | I13: 883 | J13: =H13-I13 -> 205 | K13: =H13/$H$7 -> 0.19557793 | L13: 0.16 | M13: 1192 | N13: 854.4 | O13: 346.6 | P13: 0.22187327 | Q13: 0.16 | R13: 1072 | S13: 882.88 | T13: 189.12 | U13: 0.20157954 | V13: 0.16 | W13: 1361 | X13: 866.4 | Y13: 494.6 | Z13: 0.24474015 | AA13: 0.16224719 | AB13: 1444 | AC13: 907.68 | AD13: 536.32 | AE13: 0.25467372 | AF13: 0.16449438 | AG13: 1422 | AH13: 860.72 | AI13: 561.28 | AJ13: 0.26891074 | AK13: 0.16674157 | AL13: 1300 | AM13: 942.4 | AN13: 357.6 | AO13: 0.24141133 | AP13: 0.17078652 | AQ13: =M13+R13+W13+AB13+AG13+AL13+H13+C13 -> 10201 | AR13: =N13+S13+X13+AC13+AH13+AM13+I13+D13 -> 7080.48 | AS13: =AQ13-AR13 -> 3120.52 | AT13: =AQ13/AQ7 -> 0.23301658 | AX13: Medicare Advantage | AY13: =BK102 -> 6941 | AZ13: =BL102 -> 6033.5 | BA13: =AY13/AY16 -> 0.056607159 | BB13: =AZ13/AZ16 -> 0.048705303 | BD13: Medicare Advantage | BE13: =AB12+AG12+AL12 -> 1256 | BF13: =AC12+AH12+AM12 -> 675.22 | BG13: =BE13/BE16 -> 0.076852475 | BH13: =BF13/BF16 -> 0.041685393 | BJ13: Medicare Advantage | BK13: =M12+R12+W12 -> 1213 | BL13: =N12+S12+X12 -> 650.92 | BM13: =BK13/BK16 -> 0.074494872 | BN13: =BL13/BL16 -> 0.040185208 | BP13: Medicare Advantage | BQ13: =C12+H12 -> 597 | BR13: =D12+I12 -> 442 | BS13: =BQ13/BQ16 -> 0.053532999 | BT13: =BR13/BR16 -> 0.040050743 | BW13: =BE13+BK13+BQ13 -> 3066
A14: Asbury Methodist Village | B14: Private Pay | C14: =1219+65 -> 1284 | D14: 1424 | E14: =C14-D14 -> -140 | F14: =C14/$H$7 -> 0.23081071 | G14: 0.25803371 | H14: 1268 | I14: 1424 | J14: =H14-I14 -> -156 | K14: =H14/$H$7 -> 0.22793457 | L14: 0.25803371 | M14: 1214 | N14: 1377.9 | O14: -163.9 | P14: 0.22427489 | Q14: 0.25803371 | R14: 1243 | S14: 1423.83 | T14: -180.83 | U14: 0.23373449 | V14: 0.25803371 | W14: 1316 | X14: 1362.3 | Y14: -46.3 | Z14: 0.23664808 | AA14: 0.25511236 | AB14: 1250 | AC14: 1392.21 | AD14: -142.21 | AE14: 0.22045855 | AF14: 0.25230337 | AG14: 1189 | AH14: 1287.89 | AI14: -98.89 | AJ14: 0.22484871 | AK14: 0.24949438 | AL14: 1348 | AM14: 1379.5 | AN14: -31.5 | AO14: 0.25032498 | AP14: 0.25 | AQ14: =M14+R14+W14+AB14+AG14+AL14+H14+C14 -> 10112 | AR14: =N14+S14+X14+AC14+AH14+AM14+I14+D14 -> 11071.63 | AS14: =AQ14-AR14 -> -959.63 | AT14: =AQ14/AQ7 -> 0.2309836 | AX14: MedicareA/MC HMO | AY14: =BK103 -> 17179 | AZ14: =BL103 -> 14408.3 | BA14: =AY14/AY16 -> 0.14010292 | BB14: =AZ14/AZ16 -> 0.1163107 | BD14: MedicareA/MC HMO | BE14: =AB13+AG13+AL13 -> 4166 | BF14: =AC13+AH13+AM13 -> 2710.8 | BG14: =BE14/BE16 -> 0.25491036 | BH14: =BF14/BF16 -> 0.16735399 | BJ14: MedicareA/MC HMO | BK14: =M13+R13+W13 -> 3625 | BL14: =N13+S13+X13 -> 2603.68 | BM14: =BK14/BK16 -> 0.22262482 | BN14: =BL14/BL16 -> 0.16074083 | BP14: MedicareA/MC HMO | BQ14: =C13+H13 -> 2410 | BR14: =D13+I13 -> 1766 | BS14: =BQ14/BQ16 -> 0.21610473 | BT14: =BR14/BR16 -> 0.16002175 | BW14: =BE14+BK14+BQ14 -> 10201
A15: Asbury Solomons | B15: Totals | C15: =SUM(C16:C21) -> 1247 | D15: =SUM(D16:D21) -> 1241 | E15: =C15-D15 -> 6 | F15: =C15/C15 -> 1 | G15: 1 | H15: =SUM(H16:H21) -> 1091 | I15: =SUM(I16:I21) -> 1241 | J15: =H15-I15 -> -150 | K15: =H15/H15 -> 1 | L15: 1 | M15: =SUM(M16:M21) -> 1038 | N15: =SUM(N16:N21) -> 1200 | O15: =M15-N15 -> -162 | P15: =M15/$M$15 -> 1 | Q15: 1 | R15: =SUM(R16:R21) -> 1004 | S15: =SUM(S16:S21) -> 1240 | T15: =R15-S15 -> -236 | U15: =R15/$R$15 -> 1 | V15: 1 | W15: =SUM(W16:W21) -> 973 | X15: =SUM(X16:X21) -> 1200 | Y15: =W15-X15 -> -227 | Z15: =W15/$W$15 -> 1 | AA15: 1 | AB15: =SUM(AB16:AB21) -> 932 | AC15: =SUM(AC16:AC21) -> 1240 | AD15: =AB15-AC15 -> -308 | AE15: =AB15/$AB$15 -> 1 | AF15: 1 | AG15: =SUM(AG16:AG21) -> 1001 | AH15: =SUM(AH16:AH21) -> 1160 | AI15: =AG15-AH15 -> -159 | AJ15: =AG15/$AG$15 -> 1 | AK15: 1 | AL15: =SUM(AL16:AL21) -> 1059 | AM15: =SUM(AM16:AM21) -> 1240 | AN15: -181 | AO15: 1 | AP15: 1 | AQ15: =M15+R15+W15+AB15+AG15+AL15+H15+C15 -> 8345 | AR15: =N15+S15+X15+AC15+AH15+AM15+I15+D15 -> 9762 | AS15: =AQ15-AR15 -> -1417 | AT15: =AQ15/AQ15 -> 1 | AX15: Private Pay | AY15: =BK104 -> 41137 | AZ15: =BL104 -> 43090.41 | BA15: =AY15/AY16 -> 0.33549182 | BB15: =AZ15/AZ16 -> 0.34784644 | BD15: Private Pay | BE15: =AB14+AG14+AL14 -> 3787 | BF15: =AC14+AH14+AM14 -> 4059.6 | BG15: =BE15/BE16 -> 0.23172 | BH15: =BF15/BF16 -> 0.25062353 | BJ15: Private Pay | BK15: =M14+R14+W14 -> 3773 | BL15: =N14+S14+X14 -> 4164.03 | BM15: =BK15/BK16 -> 0.23171406 | BN15: =BL15/BL16 -> 0.25707063 | BP15: Private Pay | BQ15: =C14+H14 -> 2552 | BR15: =D14+I14 -> 2848 | BS15: =BQ15/BQ16 -> 0.22883788 | BT15: =BR15/BR16 -> 0.25806452 | BW15: =BE15+BK15+BQ15 -> 10112
A16: Asbury Solomons | B16: Medicaid | C16: 416 | D16: 433 | E16: =C16-D16 -> -17 | F16: =C16/$H$15 -> 0.38130156 | G16: 0.349 | H16: 420 | I16: 433 | J16: =H16-I16 -> -13 | K16: =H16/$H$15 -> 0.38496792 | L16: 0.349 | M16: 376 | N16: 418.8 | O16: =M16-N16 -> -42.8 | P16: =M16/$M$15 -> 0.36223507 | Q16: 0.349 | R16: 372 | S16: 432.76 | T16: =R16-S16 -> -60.76 | U16: =R16/$R$15 -> 0.37051793 | V16: 0.349 | W16: 360 | X16: 418.8 | Y16: =W16-X16 -> -58.8 | Z16: =W16/$W$15 -> 0.36998972 | AA16: 0.349 | AB16: 372 | AC16: 432.76 | AD16: =AB16-AC16 -> -60.76 | AE16: =AB16/$AB$15 -> 0.39914163 | AF16: 0.349 | AG16: 334 | AH16: 404.84 | AI16: =AG16-AH16 -> -70.84 | AJ16: =AG16/$AG$15 -> 0.33366633 | AK16: 0.349 | AL16: 340 | AM16: 432.76 | AN16: -92.76 | AO16: 0.3210576 | AP16: 0.349 | AQ16: =M16+R16+W16+AB16+AG16+AL16+H16+C16 -> 2990 | AR16: =N16+S16+X16+AC16+AH16+AM16+I16+D16 -> 3406.72 | AS16: =AQ16-AR16 -> -416.72 | AT16: =AQ16/AQ15 -> 0.35829838 | AY16: =SUM(AY9:AY15) -> 122617 | AZ16: =SUM(AZ9:AZ15) -> 123877.68 | BA16: =SUM(BA9:BA15) -> 1 | BB16: =AZ16/AZ16 -> 1 | BE16: =SUM(BE9:BE15) -> 16343 | BF16: =SUM(BF9:BF15) -> 16198 | BG16: =SUM(BG9:BG15) -> 1 | BH16: =BF16/BF16 -> 1 | BK16: =SUM(BK9:BK15) -> 16283 | BL16: =SUM(BL9:BL15) -> 16198 | BM16: =SUM(BM9:BM15) -> 1 | BN16: =BL16/BL16 -> 1 | BQ16: =SUM(BQ9:BQ15) -> 11152 | BR16: =SUM(BR9:BR15) -> 11036 | BS16: =SUM(BS9:BS15) -> 1 | BT16: =BR16/BR16 -> 1 | BW16: =BE16+BK16+BQ16 -> 43778
B17: Managed Care | C17: =19+3 -> 22 | D17: 0 | E17: =C17-D17 -> 22 | F17: =C17/$H$15 -> 0.020164986 | H17: 30 | I17: 0 | J17: =H17-I17 -> 30 | K17: =H17/$H$15 -> 0.027497709 | M17: 18 | N17: 0 | O17: =M17-N17 -> 18 | P17: =M17/$M$15 -> 0.01734104 | AG17: 0 | AH17: 0 | AQ17: =M17+R17+W17+AB17+AG17+AL17+H17+C17 -> 70 | AR17: =N17+S17+X17+AC17+AH17+AM17+I17+D17 -> 0 | AS17: =AQ17-AR17 -> 70 | AT17: =AQ17/AQ15 -> 0.0083882564
B18: MA Pending | C18: 31 | D18: 0 | E18: =C18-D18 -> 31 | F18: =C18/$H$15 -> 0.028414299 | H18: 31 | I18: 0 | J18: =H18-I18 -> 31 | K18: =H18/$H$15 -> 0.028414299 | M18: 10 | N18: 0 | O18: =M18-N18 -> 10 | P18: =M18/$M$15 -> 0.0096339114 | AQ18: =M18+R18+W18+AB18+AG18+AL18+H18+C18 -> 72 | AR18: =N18+S18+X18+AC18+AH18+AM18+I18+D18 -> 0 | AS18: =AQ18-AR18 -> 72 | AT18: =AQ18/AQ15 -> 0.0086279209
A19: Asbury Solomons | B19: Medicare Advantage | C19: 10 | D19: 0 | E19: =C19-D19 -> 10 | F19: =C19/$H$15 -> 0.0091659028 | G19: - | H19: 10 | I19: 0 | J19: =H19-I19 -> 10 | K19: =H19/$H$15 -> 0.0091659028 | L19: - | M19: 0 | N19: 0 | O19: =M19-N19 -> 0 | P19: =M19/$M$15 -> 0 | Q19: - | S19: 0 | T19: =R19-S19 -> 0 | U19: =R19/$R$15 -> 0 | V19: - | W19: 28 | X19: 0 | Y19: =W19-X19 -> 28 | Z19: =W19/$W$15 -> 0.028776978 | AA19: - | AB19: 13 | AC19: 0 | AD19: =AB19-AC19 -> 13 | AE19: =AB19/$AB$15 -> 0.013948498 | AF19: - | AG19: =23+14 -> 37 | AH19: 0 | AI19: =AG19-AH19 -> 37 | AJ19: =AG19/$AG$15 -> 0.036963037 | AK19: - | AL19: 25 | AM19: 0 | AN19: 25 | AO19: 0.023607177 | AP19: 0 | AQ19: =M19+R19+W19+AB19+AG19+AL19+H19+C19 -> 123 | AR19: =N19+S19+X19+AC19+AH19+AM19+I19+D19 -> 0 | AS19: =AQ19-AR19 -> 123 | AT19: =AQ19/AQ15 -> 0.014739365 | BD19: Q1 2024 | BJ19: Q2 2024 | BP19: =BP6 -> Q3 2024
A20: Asbury Solomons | B20: MedicareA/MC HMO | C20: 160 | D20: 109 | E20: =C20-D20 -> 51 | F20: =C20/$H$15 -> 0.14665445 | G20: 0.0875 | H20: 116 | I20: 109 | J20: =H20-I20 -> 7 | K20: =H20/$H$15 -> 0.10632447 | L20: 0.0875 | M20: 165 | N20: 105 | O20: =M20-N20 -> 60 | P20: =M20/$M$15 -> 0.15895954 | Q20: 0.0875 | R20: 108 | S20: 108.5 | T20: =R20-S20 -> -0.5 | U20: =R20/$R$15 -> 0.10756972 | V20: 0.0875 | W20: 112 | X20: 105 | Y20: =W20-X20 -> 7 | Z20: =W20/$W$15 -> 0.11510791 | AA20: 0.0875 | AB20: 106 | AC20: 108.5 | AD20: =AB20-AC20 -> -2.5 | AE20: =AB20/$AB$15 -> 0.11373391 | AF20: 0.0875 | AG20: 134 | AH20: 101.5 | AI20: =AG20-AH20 -> 32.5 | AJ20: =AG20/$AG$15 -> 0.13386613 | AK20: 0.0875 | AL20: 179 | AM20: 108.5 | AN20: 70.5 | AO20: 0.16902738 | AP20: 0.0875 | AQ20: =M20+R20+W20+AB20+AG20+AL20+H20+C20 -> 1080 | AR20: =N20+S20+X20+AC20+AH20+AM20+I20+D20 -> 855 | AS20: =AQ20-AR20 -> 225 | AT20: =AQ20/AQ15 -> 0.12941881 | BD20: Total by payer | BI20: AS | BJ20: Total by payer | BO20: AS | BP20: Total by payer
A21: Asbury Solomons | B21: Private Pay | C21: 608 | D21: 699 | E21: =C21-D21 -> -91 | F21: =C21/$H$15 -> 0.55728689 | G21: 0.5635 | H21: 484 | I21: 699 | J21: =H21-I21 -> -215 | K21: =H21/$H$15 -> 0.4436297 | L21: 0.5635 | M21: 469 | N21: 676.2 | O21: =M21-N21 -> -207.2 | P21: =M21/$M$15 -> 0.45183044 | Q21: 0.5635 | R21: 524 | S21: 698.74 | T21: =R21-S21 -> -174.74 | U21: =R21/$R$15 -> 0.52191235 | V21: 0.5635 | W21: 473 | X21: 676.2 | Y21: =W21-X21 -> -203.2 | Z21: =W21/$W$15 -> 0.48612539 | AA21: 0.5635 | AB21: 441 | AC21: 698.74 | AD21: =AB21-AC21 -> -257.74 | AE21: =AB21/$AB$15 -> 0.47317597 | AF21: 0.5635 | AG21: 496 | AH21: 653.66 | AI21: =AG21-AH21 -> -157.66 | AJ21: =AG21/$AG$15 -> 0.4955045 | AK21: 0.5635 | AL21: 515 | AM21: 698.74 | AN21: -183.74 | AO21: 0.48630784 | AP21: 0.5635 | AQ21: =M21+R21+W21+AB21+AG21+AL21+H21+C21 -> 4010 | AR21: =N21+S21+X21+AC21+AH21+AM21+I21+D21 -> 5500.28 | AS21: =AQ21-AR21 -> -1490.28 | AT21: =AQ21/AQ15 -> 0.48052726 | BE21: Actual | BF21: Budget | BG21: Actual | BH21: Budget | BK21: Actual | BL21: Budget | BM21: Actual | BN21: Budget | BQ21: Actual | BR21: Budget | BS21: Actual | BT21: Budget
A22: Bethany Village | B22: Totals | C22: =SUM(C23:C27) -> 1921 | D22: =SUM(D23:D27) -> 2032 | E22: =C22-D22 -> -111 | F22: =C22/$H$22 -> 0.94770597 | G22: 1 | H22: =SUM(H23:H27) -> 2027 | I22: =SUM(I23:I27) -> 2032 | J22: =H22-I22 -> -5 | K22: =H22/$H$22 -> 1 | L22: 1 | M22: =SUM(M23:M27) -> 1949 | N22: =SUM(N23:N27) -> 1966.5 | O22: =M22-N22 -> -17.5 | P22: =M22/$M$22 -> 1 | Q22: 1 | R22: =SUM(R23:R27) -> 2047 | S22: =SUM(S23:S27) -> 2032.05 | T22: =R22-S22 -> 14.95 | U22: =R22/$R$22 -> 1 | V22: 1 | W22: =SUM(W23:W27) -> 1975 | X22: =SUM(X23:X27) -> 1966.5 | Y22: =W22-X22 -> 8.5 | Z22: =W22/$W$22 -> 1 | AA22: 1 | AB22: =SUM(AB23:AB27) -> 2034 | AC22: =SUM(AC23:AC27) -> 2032.05 | AD22: =AB22-AC22 -> 1.95 | AE22: 1 | AF22: 1 | AG22: =SUM(AG23:AG27) -> 1946 | AH22: =SUM(AH23:AH27) -> 1900.95 | AI22: 45.05 | AJ22: 1 | AK22: 1 | AL22: 2098 | AM22: 2032.05 | AN22: 65.95 | AO22: 1 | AP22: 1 | AQ22: =M22+R22+W22+AB22+AG22+AL22+H22+C22 -> 15997 | AR22: =N22+S22+X22+AC22+AH22+AM22+I22+D22 -> 15994.1 | AS22: =AQ22-AR22 -> 2.9 | AT22: =AQ22/AQ22 -> 1 | BD22: Hospice | BG22: =BE22/BE29 -> 0 | BH22: =BF22/BF29 -> 0 | BJ22: Hospice | BM22: =BK22/BK29 -> 0 | BN22: =BL22/BL29 -> 0 | BP22: Hospice | BS22: =BQ22/BQ29 -> 0 | BT22: =BR22/BR29 -> 0
